<?xml version="1.0" ?>
<robot name="AR_bot" xmlns:xacro="http://ros.org/wiki/xacro">
    <xacro:include filename="$(find ar_description)/urdf/common_properties.xacro"/>

    <link name="base_footprint"/>

    <joint name="base_joint" type="fixed">
        <parent link="base_footprint"/>
        <child link="base_link"/>
        <origin xyz="0.0 0.0 0.0" rpy="0 0 0"/>
    </joint>

    <link name="base_link">
        <visual>
            <origin xyz="0.1 0.18 0.0" rpy="0 0 ${M_PI/2}"/>
            <geometry>
                <mesh filename="package://ar_description/meshes/base/Main_Frame.stl" scale="0.001 0.001 0.001"/>
            </geometry>
            <material name="white"/>
        </visual>

        <collision>
            <origin xyz="-0.032 0 0.070" rpy="0 0 0"/>
            <geometry>
                <box size="0.140 0.140 0.140"/>
            </geometry>
        </collision>

        <inertial>
            <origin xyz="-0.032 0 0" rpy="0 0 0"/>
            <mass value="1"/>
            <inertia ixx="0.01" ixy="0.0" ixz="0.0"
                     iyy="0.01" iyz="0.0" 
                     izz="0.01"/>
        </inertial>
    </link>

    <joint name="wheel_left_joint" type="continuous">
        <parent link="base_link"/>
        <child link="wheel_left_link"/>
        <!-- <origin xyz="-0.050 -0.14 0.05" rpy="${-M_PI*0.5} ${M_PI} 0"/> -->
	<origin xyz="0 -0.14 0.05" rpy="${-M_PI*0.5} 0 0"/>
        <axis xyz="0 0 1"/>
    </joint>

    <link name="wheel_left_link">
        <visual>
        <!--
            <origin xyz="0.185 0.05 -0.17" rpy="${M_PI*0.5} 0 0"/>
            <geometry>
                <mesh filename="package://AR_description/meshes/wheel/rwheel.stl" scale = "0.001 0.001 0.001"/>
            </geometry>
        -->
            <!-- <origin xyz="0 0 0" rpy="${M_PI*0.5} 0 0"/> -->
	    <origin xyz="0 0 0" rpy="${M_PI*0.5} 0 0"/>        
	    <geometry>
                <mesh filename="package://ar_description/meshes/wheel/Tlwheel.stl" scale="0.0013 0.0007 0.0013"/>
            </geometry>
            <material name="dark"/>
        </visual>

        <collision>
            <origin xyz="0 0 0" rpy="0 0 0"/>
            <geometry>
                <cylinder length="0.018" radius="0.033"/>
            </geometry>
        </collision>

        <inertial>
            <origin xyz="0 0 0"/>
            <mass value="0.01"/>
            <inertia ixx="0.001" ixy="0.0" ixz="0.0"
                      iyy="0.001" iyz="0.0"
                      izz="0.001"/>            
        </inertial>
    </link>

    <joint name="wheel_right_joint" type="continuous">
        <parent link="base_link"/>
        <child link="wheel_right_link"/>
        <!--<origin xyz="-0.05 0.14 0.05" rpy="${-M_PI*0.5} ${M_PI} 0"/>-->
	<origin xyz="0 0.14 0.05" rpy="${-M_PI*0.5} 0 0"/>
        <axis xyz="0 0 1"/>
    </joint>

    <link name="wheel_right_link">
        <visual>
        <!--
            <origin xyz="0.18 0.05 -0.18" rpy="${M_PI*0.5} 0 0"/>
            <geometry>
                <mesh filename="package://AR_description/meshes/wheel/lwheel.stl" scale="0.001 0.001 0.001"/>
            </geometry>
        -->
            <!-- <origin xyz="0 0 0" rpy="${M_PI*0.5} 0 0"/> -->
	    <origin xyz="0 0 0" rpy="${M_PI*0.5} 0 0"/>
            <geometry>
                <mesh filename="package://ar_description/meshes/wheel/Trwheel.stl" scale="0.0013 0.0007 0.0013"/>
            </geometry>
            <material name="dark"/>
        </visual>

        <collision>
            <origin xyz="0 0 0" rpy="0 0 0"/>
            <geometry>
                <cylinder length="0.018" radius="0.033"/>
            </geometry>
        </collision>

        <inertial>
            <origin xyz="0 0 0"/>
            <mass value="0.01"/>
            <inertia ixx="0.001" ixy="0.0" ixz="0.0"
                     iyy="0.001" iyz="0.0" 
                     izz="0.001"/>
        </inertial>
    </link>

    <joint name="caster_back_joint" type="fixed">
        <parent link="base_link"/>
        <child link="caster_back_link"/>
        <origin xyz="-0.181 0 -0.004" rpy="0 0 0"/>
    </joint>

    <link name="caster_back_link">
        <collision>
            <origin xyz="0 0 0" rpy="0 0 0"/>
            <geometry>
                <box size="0.030 0.010 0.020"/>
            </geometry>
        </collision>

        <inertial>
            <origin xyz="0 0 0"/>
            <mass value="0.01"/>
            <inertia ixx="0.001" ixy="0.0" ixz="0.0"
                     iyy="0.001" iyz="0.0" 
                     izz="0.001"/>
        </inertial>
    </link>

    <joint name="imu_joint" type="fixed">
        <parent link="base_link"/>
        <child link="imu_link"/>
        <origin xyz="0 0 0.09" rpy="0 0 0"/>
    </joint>

    <link name="imu_link"/>

    <joint name="scan_joint" type="fixed">
        <parent link="base_link"/>
        <child link="base_scan"/>
        <origin xyz="-0.1 0 0.273" rpy="0 0 0"/>
    </joint>

    <link name="base_scan">
        <visual>
            <origin xyz="0 0 0.0" rpy="0 0 0"/>
            <geometry>
                <mesh filename="package://ar_description/meshes/sensor/lds.stl" scale="0.001 0.001 0.001"/>
            </geometry>
            <material name="dark"/>
        </visual>

        <collision>
            <origin xyz="0 0 0" rpy="0 0 0"/>
            <geometry>
                <cylinder length="0.0408" radius="0.070"/>
            </geometry>
        </collision>

        <inertial>
            <mass value="0.01"/>
            <origin xyz="0 0 0"/>
            <inertia ixx="0.001" ixy="0.0" ixz="0.0"
                     iyy="0.001" iyz="0.0" 
                     izz="0.001"/>
        </inertial>
    </link>

</robot>

            



